Traceback (most recent call last):
  File "/usr/local/bin/certbot", line 11, in <module>
    load_entry_point('certbot==0.10.1', 'console_scripts', 'certbot')()
  File "/usr/local/Cellar/certbot/0.10.1_1/libexec/lib/python2.7/site-packages/certbot/main.py", line 828, in main
    args = cli.prepare_and_parse_args(plugins, cli_args)
  File "/usr/local/Cellar/certbot/0.10.1_1/libexec/lib/python2.7/site-packages/certbot/cli.py", line 1056, in prepare_and_parse_args
    return helpful.parse_args()
  File "/usr/local/Cellar/certbot/0.10.1_1/libexec/lib/python2.7/site-packages/certbot/cli.py", line 516, in parse_args
    parsed_args = self.parser.parse_args(self.args)
  File "/usr/local/Cellar/certbot/0.10.1_1/libexec/lib/python2.7/site-packages/configargparse.py", line 402, in parse_args
    env_vars = env_vars)
  File "/usr/local/Cellar/certbot/0.10.1_1/libexec/lib/python2.7/site-packages/configargparse.py", line 556, in parse_known_args
    self, args=args, namespace=namespace)
  File "/usr/local/opt/python/Frameworks/Python.framework/Versions/2.7/lib/python2.7/argparse.py", line 1733, in parse_known_args
    namespace, args = self._parse_known_args(args, namespace)
  File "/usr/local/opt/python/Frameworks/Python.framework/Versions/2.7/lib/python2.7/argparse.py", line 1939, in _parse_known_args
    start_index = consume_optional(start_index)
  File "/usr/local/opt/python/Frameworks/Python.framework/Versions/2.7/lib/python2.7/argparse.py", line 1879, in consume_optional
    take_action(action, args, option_string)
  File "/usr/local/opt/python/Frameworks/Python.framework/Versions/2.7/lib/python2.7/argparse.py", line 1807, in take_action
    action(self, namespace, argument_values, option_string)
  File "/usr/local/Cellar/certbot/0.10.1_1/libexec/lib/python2.7/site-packages/certbot/cli.py", line 1211, in __call__
    "Unrecognized challenges: {0}".format(unrecognized))
ArgumentTypeError: Unrecognized challenges: tls-
